Workbook

Sheet Dashboard
A1: 💰 PERSONAL FINANCE DASHBOARD
A2: Live overview — auto-updates as you fill in Income, Budget & Expenses sheets
B4: 📊 THIS MONTH AT A GLANCE | E4: 🎯 BUDGET ALLOCATION
B5: Total Monthly Income | C5: =Income!C15 -> 50000 | E5: Needs (Essentials) | F5: =Budget!E16 -> 18000
B6: Total Budgeted | C6: =Budget!E45 -> 23450 | E6: Wants (Lifestyle) | F6: =Budget!E27 -> 450
B7: Total Actual Expenses | C7: =SUMIF(Expenses!E:E,"<>",Expenses!D:D) -> 23450 | E7: Savings & Investments | F7: =Budget!E44 -> 0
B8: Net Savings (Income - Spend) | C8: =C5-C7 -> 26550 | E8: Total Allocated | F8: =F5+F6+F7 -> 18450
B9: Savings Rate | C9: =IFERROR(C8/C5,0) -> 0.531 | E9: Unallocated (Buffer) | F9: =C5-F8 -> 31550
B12: 🏆 GOALS PROGRESS
B13: Goal | C13: Target | E13: Saved | F13: Progress | G13: Progress
B14: =IFERROR(Goals!B5,"") -> Emergency Fund (6 months expenses) | C14: =IFERROR(Goals!C5,0) -> 300000 | E14: =IFERROR(Goals!D5,0) -> 50000 | F14: =IFERROR(Goals!E5,0) -> 0.16666667
B15: =IFERROR(Goals!B6,"") -> Down payment for home | C15: =IFERROR(Goals!C6,0) -> 1500000 | E15: =IFERROR(Goals!D6,0) -> 100000 | F15: =IFERROR(Goals!E6,0) -> 0.066666667
B16: =IFERROR(Goals!B7,"") -> Vacation - Goa Trip | C16: =IFERROR(Goals!C7,0) -> 60000 | E16: =IFERROR(Goals!D7,0) -> 10000 | F16: =IFERROR(Goals!E7,0) -> 0.16666667
B17: =IFERROR(Goals!B8,"") -> New laptop | C17: =IFERROR(Goals!C8,0) -> 80000 | E17: =IFERROR(Goals!D8,0) -> 0 | F17: =IFERROR(Goals!E8,0) -> 0
B18: =IFERROR(Goals!B9,"") -> Retirement Corpus (long-term) | C18: =IFERROR(Goals!C9,0) -> 5000000 | E18: =IFERROR(Goals!D9,0) -> 200000 | F18: =IFERROR(Goals!E9,0) -> 0.04
B21: 💡 HOW TO USE → 1) Fill IN Income sheet 2) Set % allocations in Budget sheet 3) Log daily spends in Expenses sheet 4) Add savings goals in Goals sheet • Blue cells = your inputs | Black = formulas | Green = pulled from another sheet

Sheet Income
A1: 💵 MONTHLY INCOME
A2: Add all your income sources below. Update each month or set as recurring.
B4: Income Source | C4: Amount (₹) | D4: Notes
B5: Primary Salary (Take-home) | C5: 50000 | D5: Net salary after tax & PF
B6: Bonus / Variable Pay | C6: 0 | D6: Average monthly portion
B7: Freelance / Side Income | C7: 0
B8: Rental Income | C8: 0
B9: Investment Returns (Dividend/Interest) | C9: 0
B10: Other Income | C10: 0
B15: TOTAL MONTHLY INCOME | C15: =SUM(C5:C13) -> 50000
B17: Projected Annual Income (×12) | C17: =C15*12 -> 600000

Sheet Budget
A1: 🎯 BUDGET ALLOCATION PLAN
A2: Set % for each category. Amounts auto-calculate from your monthly income. Edit categories to fit your life.
B3: Monthly Income (from Income sheet) | E3: =Income!C15 -> 50000
B4: Category | C4: % of Income | D4: Planned (₹) | E4: Actual Spent (₹) | F4: Difference
B5: 🏠 NEEDS — Essentials (target ~50%)
B6: Rent / Home EMI | C6: 0.25 | D6: =$E$3*C6 -> 12500 | E6: =SUMIF(Expenses!C:C,B6,Expenses!D:D) -> 15000 | F6: =D6-E6 -> -2500
B7: Utilities (Electricity, Water, Gas) | C7: 0.03 | D7: =$E$3*C7 -> 1500 | E7: =SUMIF(Expenses!C:C,B7,Expenses!D:D) -> 0 | F7: =D7-E7 -> 1500
B8: Internet & Mobile | C8: 0.02 | D8: =$E$3*C8 -> 1000 | E8: =SUMIF(Expenses!C:C,B8,Expenses!D:D) -> 0 | F8: =D8-E8 -> 1000
B9: Groceries & Household | C9: 0.08 | D9: =$E$3*C9 -> 4000 | E9: =SUMIF(Expenses!C:C,B9,Expenses!D:D) -> 2200 | F9: =D9-E9 -> 1800
B10: Transportation / Fuel | C10: 0.05 | D10: =$E$3*C10 -> 2500 | E10: =SUMIF(Expenses!C:C,B10,Expenses!D:D) -> 800 | F10: =D10-E10 -> 1700
B11: Insurance Premiums (Health, Life, Vehicle) | C11: 0.03 | D11: =$E$3*C11 -> 1500 | E11: =SUMIF(Expenses!C:C,B11,Expenses!D:D) -> 0 | F11: =D11-E11 -> 1500
B12: Healthcare / Medicines | C12: 0.02 | D12: =$E$3*C12 -> 1000 | E12: =SUMIF(Expenses!C:C,B12,Expenses!D:D) -> 0 | F12: =D12-E12 -> 1000
B13: EMIs / Loan Repayments | C13: 0.02 | D13: =$E$3*C13 -> 1000 | E13: =SUMIF(Expenses!C:C,B13,Expenses!D:D) -> 0 | F13: =D13-E13 -> 1000
B14: Education / School Fees | C14: 0 | D14: =$E$3*C14 -> 0 | E14: =SUMIF(Expenses!C:C,B14,Expenses!D:D) -> 0 | F14: =D14-E14 -> 0
B15: Domestic Help / Childcare | C15: 0 | D15: =$E$3*C15 -> 0 | E15: =SUMIF(Expenses!C:C,B15,Expenses!D:D) -> 0 | F15: =D15-E15 -> 0
B16: SUBTOTAL — NEEDS | C16: =SUM(C6:C15) -> 0.5 | D16: =SUM(D6:D15) -> 25000 | E16: =SUM(E6:E15) -> 18000 | F16: =D16-E16 -> 7000
B17: ✨ WANTS — Lifestyle (target ~30%)
B18: Dining Out / Food Delivery | C18: 0.05 | D18: =$E$3*C18 -> 2500 | E18: =SUMIF(Expenses!C:C,B18,Expenses!D:D) -> 450 | F18: =D18-E18 -> 2050
B19: Entertainment (Movies, OTT, Games) | C19: 0.03 | D19: =$E$3*C19 -> 1500 | E19: =SUMIF(Expenses!C:C,B19,Expenses!D:D) -> 0 | F19: =D19-E19 -> 1500
B20: Shopping (Clothes, Gadgets) | C20: 0.05 | D20: =$E$3*C20 -> 2500 | E20: =SUMIF(Expenses!C:C,B20,Expenses!D:D) -> 0 | F20: =D20-E20 -> 2500
B21: Subscriptions (Netflix, Spotify, etc.) | C21: 0.02 | D21: =$E$3*C21 -> 1000 | E21: =SUMIF(Expenses!C:C,B21,Expenses!D:D) -> 0 | F21: =D21-E21 -> 1000
B22: Personal Care / Grooming | C22: 0.02 | D22: =$E$3*C22 -> 1000 | E22: =SUMIF(Expenses!C:C,B22,Expenses!D:D) -> 0 | F22: =D22-E22 -> 1000
B23: Travel & Vacations (monthly set-aside) | C23: 0.05 | D23: =$E$3*C23 -> 2500 | E23: =SUMIF(Expenses!C:C,B23,Expenses!D:D) -> 0 | F23: =D23-E23 -> 2500
B24: Hobbies & Recreation | C24: 0.02 | D24: =$E$3*C24 -> 1000 | E24: =SUMIF(Expenses!C:C,B24,Expenses!D:D) -> 0 | F24: =D24-E24 -> 1000
B25: Gifts & Celebrations | C25: 0.02 | D25: =$E$3*C25 -> 1000 | E25: =SUMIF(Expenses!C:C,B25,Expenses!D:D) -> 0 | F25: =D25-E25 -> 1000
B26: Miscellaneous | C26: 0.04 | D26: =$E$3*C26 -> 2000 | E26: =SUMIF(Expenses!C:C,B26,Expenses!D:D) -> 0 | F26: =D26-E26 -> 2000
B27: SUBTOTAL — WANTS | C27: =SUM(C18:C26) -> 0.3 | D27: =SUM(D18:D26) -> 15000 | E27: =SUM(E18:E26) -> 450 | F27: =D27-E27 -> 14550
B28: 💰 SAVINGS & INVESTMENTS (target ~20%)
B29: Emergency Fund (Liquid Savings) | C29: 0.05 | D29: =$E$3*C29 -> 2500 | E29: =SUMIF(Expenses!C:C,B29,Expenses!D:D) -> 0 | F29: =D29-E29 -> 2500
B30: Mutual Fund SIPs (Equity) | C30: 0.05 | D30: =$E$3*C30 -> 2500 | E30: =SUMIF(Expenses!C:C,B30,Expenses!D:D) -> 5000 | F30: =D30-E30 -> -2500
B31: Mutual Fund SIPs (Debt / Hybrid) | C31: 0.02 | D31: =$E$3*C31 -> 1000 | E31: =SUMIF(Expenses!C:C,B31,Expenses!D:D) -> 0 | F31: =D31-E31 -> 1000
B32: Direct Stocks | C32: 0.02 | D32: =$E$3*C32 -> 1000 | E32: =SUMIF(Expenses!C:C,B32,Expenses!D:D) -> 0 | F32: =D32-E32 -> 1000
B33: PPF / EPF / VPF | C33: 0.02 | D33: =$E$3*C33 -> 1000 | E33: =SUMIF(Expenses!C:C,B33,Expenses!D:D) -> 0 | F33: =D33-E33 -> 1000
B34: NPS (Retirement) | C34: 0.01 | D34: =$E$3*C34 -> 500 | E34: =SUMIF(Expenses!C:C,B34,Expenses!D:D) -> 0 | F34: =D34-E34 -> 500
B35: Fixed Deposit / RD | C35: 0.01 | D35: =$E$3*C35 -> 500 | E35: =SUMIF(Expenses!C:C,B35,Expenses!D:D) -> 0 | F35: =D35-E35 -> 500
B36: Gold (SGB / Digital Gold) | C36: 0.01 | D36: =$E$3*C36 -> 500 | E36: =SUMIF(Expenses!C:C,B36,Expenses!D:D) -> 0 | F36: =D36-E36 -> 500
B37: Crypto (high-risk, optional) | C37: 0 | D37: =$E$3*C37 -> 0 | E37: =SUMIF(Expenses!C:C,B37,Expenses!D:D) -> 0 | F37: =D37-E37 -> 0
B38: Real Estate Fund / REIT | C38: 0 | D38: =$E$3*C38 -> 0 | E38: =SUMIF(Expenses!C:C,B38,Expenses!D:D) -> 0 | F38: =D38-E38 -> 0
B39: Children's Education Fund | C39: 0 | D39: =$E$3*C39 -> 0 | E39: =SUMIF(Expenses!C:C,B39,Expenses!D:D) -> 0 | F39: =D39-E39 -> 0
B40: Term Insurance Premium | C40: 0 | D40: =$E$3*C40 -> 0 | E40: =SUMIF(Expenses!C:C,B40,Expenses!D:D) -> 0 | F40: =D40-E40 -> 0
...

Sheet Expenses
A1: 📝 EXPENSE TRACKER
A2: Log every expense. Pick the same Category name as in Budget sheet — Actual Spent will auto-update there.
B4: Date | C4: Category (must match Budget) | D4: Amount (₹) | E4: Notes / Description
B5: 2026-05-01 | C5: Rent / Home EMI | D5: 15000 | E5: May rent
B6: 2026-05-02 | C6: Groceries & Household | D6: 2200 | E6: Big Bazaar weekly
B7: 2026-05-03 | C7: Transportation / Fuel | D7: 800 | E7: Petrol
B8: 2026-05-04 | C8: Dining Out / Food Delivery | D8: 450 | E8: Swiggy dinner
B9: 2026-05-05 | C9: Mutual Fund SIPs (Equity) | D9: 5000 | E9: Nifty Index SIP

Sheet Lists
A1: Rent / Home EMI
A2: Utilities (Electricity, Water, Gas)
A3: Internet & Mobile
A4: Groceries & Household
A5: Transportation / Fuel
A6: Insurance Premiums (Health, Life, Vehicle)
A7: Healthcare / Medicines
A8: EMIs / Loan Repayments
A9: Education / School Fees
A10: Domestic Help / Childcare
A11: Dining Out / Food Delivery
A12: Entertainment (Movies, OTT, Games)
... A33: Discretionary Savings

Sheet Goals
A1: 🏆 SAVINGS & INVESTMENT GOALS
A2: Set targets, track progress, and see how long until each goal is met at your current saving pace.
B4: Goal Name | C4: Target (₹) | D4: Saved So Far (₹) | E4: % Complete | F4: Monthly Contribution | G4: Months to Goal
B5: Emergency Fund (6 months expenses) | C5: 300000 | D5: 50000 | E5: =IFERROR(D5/C5,0) -> 0.16666667 | F5: 5000 | G5: =IFERROR(IF(F5=0,"Set monthly amt",ROUNDUP((C5-D5)/F5,0)),"-") -> 50
B6: Down payment for home | C6: 1500000 | D6: 100000 | E6: =IFERROR(D6/C6,0) -> 0.066666667 | F6: 15000 | G6: =IFERROR(IF(F6=0,"Set monthly amt",ROUNDUP((C6-D6)/F6,0)),"-") -> 94
B7: Vacation - Goa Trip | C7: 60000 | D7: 10000 | E7: =IFERROR(D7/C7,0) -> 0.16666667 | F7: 5000 | G7: =IFERROR(IF(F7=0,"Set monthly amt",ROUNDUP((C7-D7)/F7,0)),"-") -> 10
B8: New laptop | C8: 80000 | D8: 0 | E8: =IFERROR(D8/C8,0) -> 0 | F8: 4000 | G8: =IFERROR(IF(F8=0,"Set monthly amt",ROUNDUP((C8-D8)/F8,0)),"-") -> 20
B9: Retirement Corpus (long-term) | C9: 5000000 | D9: 200000 | E9: =IFERROR(D9/C9,0) -> 0.04 | F9: 10000 | G9: =IFERROR(IF(F9=0,"Set monthly amt",ROUNDUP((C9-D9)/F9,0)),"-") -> 480
E10: =IFERROR(D10/C10,0) -> 0 | G10: =IFERROR(IF(F10=0,"",ROUNDUP((C10-D10)/F10,0)),"")
E11: =IFERROR(D11/C11,0) -> 0 | G11: =IFERROR(IF(F11=0,"",ROUNDUP((C11-D11)/F11,0)),"")
E12: =IFERROR(D12/C12,0) -> 0 | G12: =IFERROR(IF(F12=0,"",ROUNDUP((C12-D12)/F12,0)),"")
E13: =IFERROR(D13/C13,0) -> 0 | G13: =IFERROR(IF(F13=0,"",ROUNDUP((C13-D13)/F13,0)),"")
E14: =IFERROR(D14/C14,0) -> 0 | G14: =IFERROR(IF(F14=0,"",ROUNDUP((C14-D14)/F14,0)),"")

Sheet Guide
A1: 📖 HOW TO USE & FINANCIAL TIPS
B3: Quick Start Guide & Personal Finance Principles
B5: STEP 1 • Fill in Income sheet | C5: Enter your monthly take-home from all sources. Total flows to every other sheet automatically.
B6: STEP 2 • Set % allocations in Budget sheet | C6: Default uses the 50/30/20 rule (Needs/Wants/Savings). Tweak the blue % cells until Grand Total = 100%.
B7: STEP 3 • Log expenses daily | C7: Pick category from dropdown so it auto-tallies into Budget's Actual Spent column.
B8: STEP 4 • Add goals | C8: List specific savings goals with target & monthly contribution. The sheet shows months to reach each one.
B9: STEP 5 • Review weekly | C9: Check Dashboard each weekend. Look for red 'Difference' cells — they signal categories you've overspent.
B11: RULE • 50 / 30 / 20 | C11: Industry classic: 50% needs, 30% wants, 20% savings & investments. A solid starting point.
B12: RULE • Emergency Fund First | C12: Build 3–6 months of expenses in a liquid savings account or sweep-in FD before chasing returns.
B13: RULE • Pay Yourself First | C13: Automate SIPs/investments on salary day so saving isn't an afterthought.
B14: RULE • Diversify Investments | C14: Mix equity (mutual funds, stocks), debt (PPF, FDs), and gold based on age and risk tolerance.
B15: RULE • Tax-Saving Sections | C15: In India: 80C (₹1.5L: PPF, ELSS, EPF), 80D (health insurance), NPS (extra ₹50k under 80CCD-1B).
B16: RULE • Insurance ≠ Investment | C16: Get pure term insurance for life cover and health insurance separately. Don't mix with investments (avoid ULIPs/endowments).
B17: RULE • Avoid Lifestyle Inflation | C17: When income rises, increase savings rate first — not just spending.
B19: ⚠️ NOTE • Not financial advice | C19: This planner is for personal tracking. For specific decisions on investments, taxes, or insurance, consult a SEBI-registered investment advisor or CA.
